Workbook

Sheet Instrucoes
A1: COMO USAR ESTA PLANILHA
A3: Células AMARELAS | B3: São os valores que você digita todo mês (líquidos, IRRF, valores de consignações, saldos de empenho). O resto é calculado automaticamente por fórmula.
A4: Células sem cor / com fórmula | B4: Não edite. Estão protegidas — se tentar mexer, o Sheets vai avisar antes.
A5: Códigos orçamentários (ex: 31.90.11.74) | B5: Veja o significado de cada um na aba "Glossario de Codigos".
A6: Aba "Cruzamento Rubricas" | B6: Os rótulos das linhas 2 a 8 foram deduzidos automaticamente cruzando valores — passe o mouse sobre a coluna A para ver a explicação e o nível de confiança.
A8: LANÇAR A FOLHA DE UM NOVO MÊS
B9: Use o menu FOPAG > "Lançar novo mês" no topo da tela. Isso cria uma cópia completa desta planilha (fórmulas e proteções inclusas), já com as células amarelas em branco, pronta para você preencher.
B10: O arquivo do mês atual não é apagado nem sobrescrito — cada mês fica com seu próprio arquivo no Google Drive.

Sheet Dashboard
A1: DASHBOARD FOPAG | T1: DADOS AUXILIARES - NÃO EDITAR
A2: ='LÍQUIDO FOLHA -1'!A3 -> LIQUIDAÇÃO DA FOLHA DE PAGAMENTO DO MÊS DE JULHO DE 2026-1 | T2: Regime | U2: Líquido
T3: ='CONSIGNAÇÕES FOLHA 1'!A3 -> LÍQUIDO DOS CONTRATOS | U3: ='CONSIGNAÇÕES FOLHA 1'!D3 -> 68692.72
B4: VALOR DA FOPAG (TOTAL DO MÊS) | E4: TOTAL LÍQUIDO (TODOS OS REGIMES) | H4: TOTAL IRRF RETIDO | K4: TOTAL DE CONSIGNAÇÕES | N4: ENCARGOS SOCIAIS (FUNDOS+INSS+PLANSAUDE) | T4: ='CONSIGNAÇÕES FOLHA 1'!A4 -> LÍQUIDO VENCIMENTO PESSOAL CIVIL RPPS | U4: ='CONSIGNAÇÕES FOLHA 1'!D4 -> 128490.03
B5: ='LÍQUIDO FOLHA -1'!F79 -> 694407.63 | E5: ='CONSIGNAÇÕES FOLHA 1'!D7 -> 471029.4 | H5: =SUM('LÍQUIDO FOLHA -1'!I15,'LÍQUIDO FOLHA -1'!I30,'LÍQUIDO FOLHA -1'!I44,'LÍQUIDO FOLHA -1'!I58) -> #ERROR! | K5: =SUM('CONSIGNAÇÕES FOLHA 1'!F14:J97) -> 119657.39 | N5: =SUM('LÍQUIDO FOLHA -1'!F68:F76) -> 104222.85 | T5: ='CONSIGNAÇÕES FOLHA 1'!A5 -> LÍQUIDO DO SUBSÍDIO RGPS | U5: ='CONSIGNAÇÕES FOLHA 1'!D5 -> 257926.4
A6: ="Diferença apurada na aba Reconciliação: " & TEXT('Reconciliacao'!B23,"R$ #,##0.00") & " — confira se esse valor é esperado (ex: RGPS/Militar fora do escopo daquela aba) antes de tratar como erro." -> #ERROR! | T6: ='CONSIGNAÇÕES FOLHA 1'!A6 -> LIQUIDO PESSOAL MILITAR | U6: ='CONSIGNAÇÕES FOLHA 1'!D6 -> 15920.25
T9: Categoria | U9: Valor
T10: Valor do Órgão para Empenho | U10: ='LÍQUIDO FOLHA -1'!F67 -> 590184.78
T11: Encargos Sociais | U11: =SUM('LÍQUIDO FOLHA -1'!F68:F76) -> 104222.85
T14: Encargo | U14: Valor
T15: ='LÍQUIDO FOLHA -1'!G68 -> FUNDO FINANCEIRO | U15: ='LÍQUIDO FOLHA -1'!F68 -> 24685.86
T16: ='LÍQUIDO FOLHA -1'!G69 -> FUNDO PREVIDENCIÁRIO | U16: ='LÍQUIDO FOLHA -1'!F69 -> 4503.31
T17: ='LÍQUIDO FOLHA -1'!G70 -> INSS | U17: ='LÍQUIDO FOLHA -1'!F70 -> 68775.92
T18: ='LÍQUIDO FOLHA -1'!G71 -> PLANSAUDE | U18: ='LÍQUIDO FOLHA -1'!F71 -> 6257.76
T20: Instituição | U20: Total (R$)
T21: =QUERY({'CONSIGNAÇÕES FOLHA 1'!E14:E97, 'CONSIGNAÇÕES FOLHA 1'!F14:F97+'CONSIGNAÇÕES FOLHA 1'!G14:G97+'CONSIGNAÇÕES FOLHA 1'!H14:H97+'CONSIGNAÇÕES FOLHA 1'!I14:I97+'CONSIGNAÇÕES FOLHA 1'!J14:J97}, "select Col1, Col2 where Col2 > 0 order by Col2 desc limit 10", 0) -> #ERROR!
T34: Rubrica (NES) | U34: Valor do Reforço (R$)
T35: =QUERY({NES!C2:C23, NES!G2:G23}, "select Col1, Col2 where Col2 > 0 order by Col2 desc limit 8", 0) -> #ERROR!
T44: Categoria | U44: Valor
T45: Líquido Total | U45: ='CONSIGNAÇÕES FOLHA 1'!D7 -> 471029.4
T46: Consignações Total | U46: =SUM('CONSIGNAÇÕES FOLHA 1'!F14:J97) -> 119657.39
T47: IRRF Total | U47: =SUM('LÍQUIDO FOLHA -1'!I15,'LÍQUIDO FOLHA -1'!I30,'LÍQUIDO FOLHA -1'!I44,'LÍQUIDO FOLHA -1'!I58) -> #ERROR!
T48: Encargos Sociais | U48: =SUM('LÍQUIDO FOLHA -1'!F68:F76) -> 104222.85

Sheet LÍQUIDO FOLHA -1
A1: PROCESSO: 2026/093010/000015 DATA ABERTURA: 21/07/2026 | F1: ULTIMA VERSÃO
A3: LIQUIDAÇÃO DA FOLHA DE PAGAMENTO DO MÊS DE JULHO DE 2026-1
D4: CONTRATOS - RGPS
A5: EVENTO | B5: NE | C5: NATUREZA | D5: RUBRICA | E5: CLASSIFICAÇÃO PAGAMENTO | F5: DESCRIÇÃO | G5: LÍQUIDO | H5: LIQUIDAÇÃO | I5: IRRF
C6: 3.31.90.04.01 | F6: Despesas Remuneração e IRRF última coluna | G6: 65892.72 | H6: =G6:G7-H7-H8-H10-H9-H12+G13+G11 -> 63167.72 | I6: 0
C7: 3.31.90.04.02 | F7: 13° Contratos e Adiantamento 13º | G7: 225 | H7: =G7 -> 225
C8: 3.31.90.13.02 | F8: Salario maternidade - INSS | G8: 0 | H8: =G8 -> 0
C9: 3.31.90.04.45 | F9: Férias Proporcionais Indenizadas | G9: 0 | H9: 0
C10: 3.31.90.04.02 | F10: Salário família INSS Contratos | G10: 0 | H10: =G10 -> 0
C11: 3.31.90.92.04 | F11: Contratos (Desp. Anterior) DEA | G11: 0
C12: 3.33.90.46 | D12: 3645 | F12: Auxílio Alimentação contratos | G12: 2500 | H12: =G12 -> 2500
B13: AJ3000005 | C13: 33.90.92 | D13: _ | E13: _ | F13: Rendimentos- Exercício anterior DEA | G13: 0 | H13: 0
C14: 3.31.90.94.01 | D14: NÃO EXIGE | E14: 211110101 | F14: Contratos Indenizações | G14: 2800 | H14: =G14 -> 2800
B15: _ | C15: _ | D15: 211.110.10X | F15: , | H15: 68692.72 | I15: =SUM(I6:I14) -> 0
D16: RPPS
A17: EVENTO | B17: NE | C17: NATUREZA | D17: RUBRICA | E17: CLASSIFICAÇÃO PAGAMENTO | F17: DESCRIÇÃO | G17: LÍQUIDO | H17: LIQUIDAÇÃO | I17: IRRF
C18: 3.31.90.05.07 | F18: Salário Familia Civil RPPS | G18: 0 | H18: =G18 -> 0 | I18: 0
C19: 3.31.90.11.43 | F19: 13° Salário Civil RPPS | G19: 32736.28 | H19: =G19 -> 32736.28
C20: 31.90.11.07 | F20: Abono permanência | G20: 0 | H20: =G20 -> 0 | I20: 0
C21: 31.90.11.07 | F21: Abono permanência 13º | G21: 0 | H21: 0
C22: 3.31.90.11.45 | F22: Férias Abono/Adicional de férias Const. Civil RPPS | G22: 113.59 | H22: =G22 -> 113.59
C23: 3.33.90.46 | D23: 3645 | F23: Auxílio Alimentação RPPS | G23: 0 | H23: =G23 -> 0
C24: 3.33.90.93.02 | F24: Ressarcimento 30%, Art. 22-B, MP 03/2024. | G24: 5172.33 | H24: =G24 -> 5172.33
C25: 3.33.90.93.02 | F25: Ressarcimento 40% Art.22-A | G25: 15935.28 | H25: =G25 -> 15935.28
C26: 3.31.90.92.11 | F26: Vencimento P. Civil (exerc. Anterior) DEA folha banco | G26: 5448.82 | H26: =G26 -> 5448.82 | I26: 0
C27: 3.31.90.11.74 | F27: Subsídios Civil RPPS (folha 1) | G27: 28173.56 | H27: =G27 -> 28173.56 | I27: 0
C28: 3.31.90.11.01 | F28: VENCIMENTO DE P. CIVIL e IRRF folha banco e ultima coluna | G28: 95035.04 | H28: =G28-(H19+H22+H25+H27+H20+H21+H23+H24) -> 12904 | I28: 21954.09
C29: 3.31.90.94.01 | F29: Venc. P. Civil. (indenizações) folha banco | G29: 28006.17 | H29: 28006.17
B30: _ | D30: 211.110.10X | E30: _ | F30: LÍQUIDO | H30: 128490.03 | I30: =SUM(I18:I29) -> 21954.09
D31: RGPS
A32: EVENTO | B32: NE | C32: NATUREZA | D32: RUBRICA | E32: CLASSIFICAÇÃO PAGAMENTO | F32: DESCRIÇÃO | G32: LÍQUIDO | H32: LIQUIDAÇÃO | I32: IRRF
C33: 3.31.90.11.43 | F33: 13° e Adiantamento Salário Civil RGPS | G33: 17777.97 | H33: =G33 -> 17777.97 | I33: 0
C34: 3.31.90.11.45 | F34: Férias Abono Const. Civil RGPS | G34: 0 | H34: =G34 -> 0
C35: 3.31.90.11.74 | F35: Subsídios Civil RPPS (folha banco) + IRRF ultima coluna | G35: 208034.53 | H35: =G35-H33-H39-H34-H40-H37-H42-H38 -> 140364.69 | I35: 15363.42
C36: 3.31.90.11.01 | F36: VENCIMENTO PESSOAL CIVIL | G36: 0 | H36: 0 | I36: 0
C37: 3.33.90.93.02 | F37: Ressarcimento 40% Art.22-A | G37: 23661.94 | H37: =G37 -> 23661.94
C38: 3.33.90.93.02 | F38: Ressarcimento 30%, Art. 22-B, MP 03/2024. | G38: 25229.93 | H38: =G38 -> 25229.93
C39: 3.31.90.13.02 | F39: Salário Maternidade INSS RGPS | G39: 0 | H39: =G39 -> 0
C40: 3.31.90.13.02 | F40: Salário família INSS RGPS | G40: 0 | H40: =G40 -> 0
C41: 3.31.90.92.11 | F41: Venc. P. Civil (Exerc. Anterior) DEA | G41: 0 | H41: 0
...

Sheet CONSIGNAÇÕES FOLHA 1
B1: FOPAG DO MÊS DE MAIO/2026 - 1
A3: LÍQUIDO DOS CONTRATOS | D3: 68692.72
A4: LÍQUIDO VENCIMENTO PESSOAL CIVIL RPPS | D4: 128490.03
A5: LÍQUIDO DO SUBSÍDIO RGPS | D5: 257926.4
A6: LIQUIDO PESSOAL MILITAR | D6: 15920.25
A7: VALOR TOTAL DO LÍQUIDO | D7: =SUM(D3:D6) -> 471029.4
A11: CONSIGNAÇÕES FOPAG
F12: 31.90.11.01 | G12: 31.90.11.74 (311.210.131) | H12: 31.90.12.01
B13: INSC. EVEN | C13: BANCO | D13: ITEM PATR. | E13: DESCRIÇÃO | F13: CIVIL RPPS | G13: CIVIL RGPS | H13: MILITAR | I13: PD (RPPS) | J13: PD (RGPS)
B14: 25.091.307/0001-76 | D14: 164 | E14: FUNDO DE PREVIDÊNCIA (FUNDO FINANCEIRO) | F14: 9341.69 | G14: 0 | H14: 2421.75
B15: 25.091.307/0001-76 | D15: 164 | E15: FUNDO DE PREVIDÊNCIA - FDO FINANCEIRO (31.90.92) DEA | F15: 624.12 | G15: 0 | H15: 70.62
B16: 25.091.307/0001-76 | D16: 70 | E16: FUNDO PREVIDÊNCIARIO segurado | F16: 3019.16 | G16: 0
B17: 25.091.307/0001-76 | D17: 70 | E17: FUNDO PREVIDÊNCIARIO (31.90.92) DEA | F17: 85.86 | G17: 0
B18: 00.394.460.0058-87 | C18: CODIGO DE BARRAS | D18: 105 | E18: INSS | F18: 0 | G18: 22841.36
B19: 00.394.460.0058-87 | C19: CODIGO DE BARRAS | D19: 105 | E19: INSS (92) DEA | G19: 0
B20: 01.786.029/0001-03 | E20: IRRF | F20: 21954.09 | G20: 15363.42 | H20: 4320.57
B21: 14.120.591/0001-45 | C21: 104, AG:0793; CC:0060006019 | D21: 189 | E21: PREV REQU (MUNICIPIO GURUPI - MANTIS) | F21: 0 | G21: 0
B22: 08.948.407/0001-57 | C22: 001, AG:00868, CC:158526 | D22: 102 | E22: INSTITUTO DE SEG. MUNICIPAL DE GOIÁS | F22: 0 | G22: 0
B23: 08.948.407/0001-57 | C23: 001, AG:00868, CC:158526 | D23: 102 | E23: INSTITUTO DE SEG. MUNICIPAL DE GOIÁS (31.90.92) DEA | F23: 0 | G23: 0
B24: 05.278.848/0001-09 | C24: 104, AG: 40657, CC: 060020073 | D24: 189 | E24: PREVIPALMAS REQUISITADO | F24: 0 | G24: 0
B25: 25.053.190/0001-36 | C25: BOLETO JUDICIAL | D25: 84 | E25: Desconto Judicial (TJTO) | F25: 0 | G25: 0
B26: 03.903.286/0001-03 | C26: 001, AG:15059, CC: 806145 | D26: 90 | E26: PLANO DE SAÚDE/PM/ MENS. /COMPART. | F26: 0 | G26: 0 | H26: =864.91+1229.21+119.92 -> 2214.04
B27: 17.327894/0001-21 | C27: 070, AG:380, CC: 0003800264961 | D27: 82 | E27: PLANSAÚDE COMPARTICIPAÇÃO | F27: 654 | G27: 888 | H27: 864.91
B28: 17.327894/0001-21 | C28: 070, AG:380, CC: 0003800264961 | D28: 83 | E28: PLANSAÚDE DEPEND. INDIRETO | F28: 0 | G28: 671.79 | H28: 0
B29: 17.327894/0001-21 | C29: 070, AG:380, CC: 0003800264961 | D29: 96 | E29: PLANSAÚDE – PARCELAMENTO | F29: 0 | G29: 0 | H29: 0
B30: 17.327894/0001-21 | C30: 070, AG:380, CC: 0003800264961 | D30: 81 | E30: PLANSAÚDE TAXA DE INSC. | F30: 0 | G30: 0 | H30: 0
B31: 38.137.329/0001-71 | C31: 001, AG: 1505, CC: 1325132 | D31: 102 | E31: ASSECAD MENSALIDADE | F31: 345.22 | G31: 49.86 | H31: 86.49
B32: 38.137.329/0001-71 | C32: 001, AG: 1886-4, CC: 325139 | D32: 102 | E32: ASSECAD PARCELAMENTO | F32: 0 | G32: 0 | H32: 0
B33: 38.137.329/0001-71 | C33: 001, AG: 1886-4, CC: 325139 | D33: 102 | E33: ASSECAD COMPARTICIP. | F33: 0 | G33: 0 | H33: 0
B34: 38.137.329/0001-71 | C34: 001, AG: 1886-4, CC: 1325139 | D34: 102 | E34: ASSECAD UNIMED | F34: 0 | G34: 0 | H34: 0
B35: 01.385.752/0001-80 | C35: 001/1505-9/48338-9 | D35: 102 | E35: ASSER-RURALTINS (PLANO DE SAÚDE | F35: 0 | G35: 0 | H35: 0
B36: 26.753.491/0001-35 | C36: 001, AG:1886, CC: 143358 | D36: 102 | E36: ASSINE COMPARTICIPAÇÃO | F36: 0 | G36: 0 | H36: 0
B37: 26.753.491/0001-35 | C37: 001, AG:1886, CC: 143358 | D37: 102 | E37: ASSINE MENSALIDADE | F37: 0 | G37: 0 | H37: 0
B38: 26.753.491/0001-35 | C38: 001, AG:1886, CC: 143358 | D38: 102 | E38: ASSINE PLANO DE SAÚDE | F38: 0 | G38: 0 | H38: 0
B39: 71.027.866.0001-34 | C39: 218, AG:0010 CC:104183 | D39: 102 | E39: Bonsucesso – cartão de credito | F39: 0 | G39: 0 | H39: 0
B40: 71.027.866/0001-34 | C40: 218, AG:0010 CC:104183 | D40: 102 | E40: BANCO BONSUCESSO S/A | F40: 0 | G40: 0
B41: 00.000.000/5099-73 | C41: 001, AG:36153, CC:57940 | D41: 78 | E41: BB CRÉD. FÁCIL (BB CONSIGNAÇÃO) | F41: 4979.09 | G41: 0 | H41: 0
B42: 61.186.680/0001-74 | C42: 341, AG:12480 CC:084061 | D42: 175 | E42: BMG – CARTÃO DE CREDITO | F42: 0 | G42: 0
B43: 61.186.680/0001-74 | C43: 341, AG:12480 CC:084061 | D43: 175 | E43: BMG CONSIGNAÇÃO | F43: 0 | G43: 0
B44: 37.238.516/0001-89 | C44: 001, AG: 1505, CC:0172642 | D44: 102 | E44: SINDEPOL - SIND. DOS DEL. (mensalidade) | F44: 0 | G44: 0
...

Sheet NES
A1: N° NE | B1: NATUREZA | C1: DEZCRIÇÃO DA NATUREZA | D1: SALDO 622.921.001 | E1: FOLHA | F1: VALOR DO REFORÇO R$
A2: 2018NE0000 | B2: 31.90.04.01 | C2: DESPESAS E REMUNERAÇÃO DOS CONTRATOS TEMPORÁRIOS | D2: ='LÍQUIDO FOLHA -1'!H6+'LÍQUIDO FOLHA -1'!H7+'CONSIGNAÇÕES FOLHA 1'!F131 -> 73367 | F2: =D2+E2 -> 73367 | G2: =F2+F4 -> 73367
A3: 2018NE0000 | B3: 31.90.04.02 | C3: 13° SALÁRIO - CONTRATOS TEMPORÁRIOS | F3: =D3 | G3: 0
A4: 2018NE0000 | B4: 31.90.04.45 | C4: FÉRIAS E ABONO DOS CONTRATO TEMP. | D4: ='LÍQUIDO FOLHA -1'!H9 -> 0 | F4: =D4 -> 0 | G4: 0
A5: 2018NE0000 | B5: 31.90.05.07 | C5: SALÁRIO FAMÍLIA CIVIL RPPS | D5: ='LÍQUIDO FOLHA -1'!H18 -> 0 | F5: =D5 -> 0
A6: 2018NE0000 | B6: 31.90.11.01 | C6: VENCIMENTO PESSOAL CIVIL RPPS | D6: ='LÍQUIDO FOLHA -1'!H28+'CONSIGNAÇÕES FOLHA 1'!F98 -> 70249.57 | F6: =D6 -> 70249.57 | G6: =F6+F7+F8+F9 -> 338671.47
A7: 2018NE0000 | B7: 31.90.11.43 | C7: 13° SALÁRIO CIVIL RPPS | D7: ='LÍQUIDO FOLHA -1'!H19+'LÍQUIDO FOLHA -1'!H33 -> 50514.25 | F7: =D7 -> 50514.25 | G7: 0
A8: 2018NE0000 | B8: 31.90.11.45 | C8: FÉRIAS E ABONO CIVIL RPPS | D8: ='LÍQUIDO FOLHA -1'!H22+'LÍQUIDO FOLHA -1'!H34 -> 113.59 | F8: =D8 -> 113.59 | G8: 0
A9: 2018NE0000 | B9: 31.90.11.74 | C9: SUBSÍDIOS CIVIL RGPS | D9: ='LÍQUIDO FOLHA -1'!G27+'LÍQUIDO FOLHA -1'!H35+'CONSIGNAÇÕES FOLHA 1'!G98 -> 217794.06 | F9: =D9 -> 217794.06 | G9: 0
A10: 2018NE0000 | B10: 31.90.13.02 | C10: SALÁRIO MATERNIDADE INSS RGPS | D10: ='LÍQUIDO FOLHA -1'!H8+'LÍQUIDO FOLHA -1'!H10+'LÍQUIDO FOLHA -1'!H39+'LÍQUIDO FOLHA -1'!H40 -> 0 | F10: =D10 -> 0 | G10: 0
A11: 2018NE0000 | B11: 31.90.92.04 | C11: CONTRATOS (DESP. DE EXERCÍCIO ANTERIOR) | D11: ='LÍQUIDO FOLHA -1'!H11 | F11: =D11 | G11: 0
A12: 2018NE0000 | B12: 31.90.92.11 | C12: VENCIMENTO PESSOAL CIVIL (EXERC. ANTERIOR) | D12: ='LÍQUIDO FOLHA -1'!H26+'LÍQUIDO FOLHA -1'!H41 -> 5448.82 | F12: =D12 -> 5448.82 | G12: =F11+F12 -> 5448.82
A13: 2018NE0000 | B13: 31.90.92.13 | C13: INSS DE EXERC. ANTERIOR | D13: 0 | F13: =D13 -> 0
A14: 2018NE0000 | B14: 31.90.92.94 | C14: INDENIZAÇÕES E RESTITUIÇÕES | F14: 0 | G14: 0
A15: 2018NE0000 | B15: 31.90.94.01 | C15: VENCIMENTO PESSOAL CIVIL INDENIZAÇÕES | D15: ='LÍQUIDO FOLHA -1'!H14+'LÍQUIDO FOLHA -1'!H29+'LÍQUIDO FOLHA -1'!H43 -> 80698.04 | F15: =D15 -> 80698.04 | G15: =F15 -> 80698.04
A16: 2018NE0000 | B16: 31.90.13.02 | C16: INSS (RGPS) | D16: ='CONSIGNAÇÕES FOLHA 1'!F141 -> 52085.18 | F16: =D16 -> 52085.18 | G16: =F10+F16+F21+F22+F23 -> 56928.68
A17: 2018NE0000 | B17: 31.90.13.99 | C17: OUTRAS OBRIGAÇÕES PATRONAIS | D17: 0 | F17: 0 | G17: 0
A18: 2018NE0000 | B18: 31.91.92.13 | C18: OBRIGAÇÕES PATRONAIS (EXERC. ANTERIOR) | D18: ='CONSIGNAÇÕES FOLHA 1'!F153+'CONSIGNAÇÕES FOLHA 1'!F161 -> 1223.68 | F18: =D18 -> 1223.68 | G18: =F18 -> 1223.68
A19: 2018NE0000 | B19: 31.91.13.01 | C19: CONTRIBUIÇÃO PATRONAL - ATIVO CIVIL | D19: ='CONSIGNAÇÕES FOLHA 1'!F146+'CONSIGNAÇÕES FOLHA 1'!F169 -> 23039.57 | F19: =D19 -> 23039.57 | G19: 0
A20: 2018NE0000 | B20: 31.91.13.03 | C20: PLANSAUDE CONTRIBUIÇÃO PATRONAL | D20: ='CONSIGNAÇÕES FOLHA 1'!F176+'CONSIGNAÇÕES FOLHA 1'!F181 -> 6257.76 | F20: =D20 -> 6257.76 | G20: =F19+F20 -> 29297.33
A21: 2018NE0000 | B21: 31.90.13.14 | C21: PREVI PALMAS REQUISITADO | D21: ='CONSIGNAÇÕES FOLHA 1'!F187 -> 0 | F21: =D21 -> 0 | G21: 0
A22: 2018NE | B22: 31.90.13.14 | C22: PREVI PAR REQUISITADO | D22: ='CONSIGNAÇÕES FOLHA 1'!F196 -> 0 | F22: =D22 -> 0
A23: 2018NE0000 | B23: 31.90.13.40 | C23: FUNDO DE PREV. DE GOIÁS | D23: ='CONSIGNAÇÕES FOLHA 1'!F202 -> 4843.5 | F23: =D23 -> 4843.5 | G23: =SUM(G2:G21) -> 585635.02
F24: =SUM(F2:F23) -> 585635.02 | G24: =F26-G23 -> 108772.61
F26: ='CONSIGNAÇÕES FOLHA 1'!F212 -> 694407.63
F27: =F26-F24 -> 108772.61
F30: =F27-F28 -> 108772.61

Sheet Reconciliacao
A1: SALÁRIOS | B1: DÉCIMO TERCEIRO | C1: FÉRIAS
B2: =B11+B14 -> 50739.25 | C2: =B10+B15 -> 113.59
A4: =B21-B4-C4 -> 250058.79 | B4: =SUM(B2) -> 50739.25 | C4: =SUM(C2) -> 113.59 | D4: =A4+B4+C4 -> 300911.63
A6: 211.110.101 | B6: 211.110.102 | C6: 211.110.103
C8: PENSÃO ALIMENTÍCIA
A9: 31.90.04.01 | B9: ='LÍQUIDO FOLHA -1'!H6 -> 63167.72 | C9: ='CONSIGNAÇÕES FOLHA 1'!F112 -> 0 | D9: =B9+C9 -> 63167.72
A10: 31.90.04.45 | B10: ='LÍQUIDO FOLHA -1'!H9 -> 0 | D10: =B10+C10 -> 0
A11: 31.90.04.02 | B11: ='LÍQUIDO FOLHA -1'!H7 -> 225 | D11: =B11+C11 -> 225
A12: 31.90.13.02 | B12: ='LÍQUIDO FOLHA -1'!H8+'LÍQUIDO FOLHA -1'!H10+'LÍQUIDO FOLHA -1'!H39+'LÍQUIDO FOLHA -1'!H40 -> 0 | D12: =B12+C12 -> 0
A13: 31.90.05.07 | B13: ='LÍQUIDO FOLHA -1'!H18 -> 0 | D13: =B13+C13 -> 0
A14: 31.90.11.43 | B14: ='LÍQUIDO FOLHA -1'!H19+'LÍQUIDO FOLHA -1'!H33 -> 50514.25 | D14: =B14+C14 -> 50514.25
A15: 31.90.11.45 | B15: ='LÍQUIDO FOLHA -1'!H22+'LÍQUIDO FOLHA -1'!H34 -> 113.59 | D15: =B15+C15 -> 113.59
A16: 31.90.11.01 | B16: ='LÍQUIDO FOLHA -1'!H28+'LÍQUIDO FOLHA -1'!H36 -> 12904 | C16: ='CONSIGNAÇÕES FOLHA 1'!F72 -> 0 | D16: =B16+C16 -> 12904
A17: 31.90.94.01 | D17: =B17+C17 -> 0
A18: 31.90.11.74 | B18: ='LÍQUIDO FOLHA -1'!H27+'LÍQUIDO FOLHA -1'!H35 -> 168538.25 | C18: ='CONSIGNAÇÕES FOLHA 1'!G72 -> 0 | D18: =B18+C18 -> 168538.25
A19: 31.90.92.11 | B19: ='LÍQUIDO FOLHA -1'!H41+'LÍQUIDO FOLHA -1'!H26 -> 5448.82 | C19: 0 | D19: =B19+C19 -> 5448.82
A20: 31.90.92.04 | B20: ='LÍQUIDO FOLHA -1'!H11 | D20: =B20+C20 -> 0
B21: =SUM(B9:B20) -> 300911.63 | C21: =SUM(C9:C19) -> 0 | D21: =SUM(D9:D20) -> 300911.63
A22: VALOR REAL | B22: ='LÍQUIDO FOLHA -1'!I62 -> 471029.4
A23: DIFERNÇA | B23: =B22-B21 -> 170117.77

Sheet Cruzamento Rubricas
A1: 31.90.04 | B1: 31.90.13 | C1: 31.90.94 | D1: 31.90.12 | E1: 31.90.11 | F1: 31.90.11.74 | G1: 31.90.11.43 | H1: 31.90.11.45 | I1: 31.90.11.07 | J1: 33.90.08 | K1: 31.91.13.01 | L1: 33.90.93. 40% | M1: 33.90.93. 30% | N1: 33.90.46 | O1: 31.91.13.03
A2: ='LÍQUIDO FOLHA -1'!H6 -> 63167.72 | B2: ='CONSIGNAÇÕES FOLHA 1'!F141 -> 52085.18 | C2: ='LÍQUIDO FOLHA -1'!H14 -> 2800 | D2: ='LÍQUIDO FOLHA -1'!H49 -> 7713.54 | E2: ='LÍQUIDO FOLHA -1'!H28 -> 12904 | F2: ='LÍQUIDO FOLHA -1'!H27 -> 28173.56 | G2: ='LÍQUIDO FOLHA -1'!H19 -> 32736.28 | H2: ='LÍQUIDO FOLHA -1'!H22 -> 113.59 | I2: ='LÍQUIDO FOLHA -1'!G20 -> 0 | J2: ='LÍQUIDO FOLHA -1'!H52 -> 0 | K2: ='CONSIGNAÇÕES FOLHA 1'!F146 -> 18683.37 | L2: ='LÍQUIDO FOLHA -1'!H25 -> 15935.28 | M2: ='LÍQUIDO FOLHA -1'!H24 -> 5172.33 | N2: ='LÍQUIDO FOLHA -1'!H23 -> 0 | O2: ='CONSIGNAÇÕES FOLHA 1'!F176 -> 6257.76
A3: ='LÍQUIDO FOLHA -1'!H7 -> 225 | B3: ='LÍQUIDO FOLHA -1'!H39 -> 0 | C3: ='LÍQUIDO FOLHA -1'!H29 -> 28006.17 | D3: ='CONSIGNAÇÕES FOLHA 1'!H98 -> 13056.01 | E3: ='CONSIGNAÇÕES FOLHA 1'!F98 -> 57345.57 | F3: ='LÍQUIDO FOLHA -1'!H35 -> 140364.69 | G3: ='LÍQUIDO FOLHA -1'!H33 -> 17777.97 | H3: ='LÍQUIDO FOLHA -1'!G34 -> 0 | I3: ='LÍQUIDO FOLHA -1'!H21 -> 0 | K3: ='CONSIGNAÇÕES FOLHA 1'!F169 -> 4356.2 | L3: ='LÍQUIDO FOLHA -1'!H37 -> 23661.94 | M3: ='LÍQUIDO FOLHA -1'!H38 -> 25229.93 | N3: ='LÍQUIDO FOLHA -1'!H42 -> 1000 | O3: ='CONSIGNAÇÕES FOLHA 1'!F181 -> 0
A4: ='LÍQUIDO FOLHA -1'!G10 -> 0 | B4: ='LÍQUIDO FOLHA -1'!H40 -> 0 | C4: ='LÍQUIDO FOLHA -1'!H43 -> 49891.87 | E4: 0 | F4: ='CONSIGNAÇÕES FOLHA 1'!G98 -> 49255.81 | G4: ='LÍQUIDO FOLHA -1'!H47 -> 48.44 | H4: ='LÍQUIDO FOLHA -1'!H48 -> 17.98 | I4: =SUM(I2:I3) -> 0 | J4: =SUM(J2:J3) -> 0 | K4: ='CONSIGNAÇÕES FOLHA 1'!F202 -> 4843.5 | L4: ='LÍQUIDO FOLHA -1'!H51 -> 3789.59 | M4: 0 | N4: ='LÍQUIDO FOLHA -1'!H12 -> 2500 | O4: 0
A5: ='CONSIGNAÇÕES FOLHA 1'!F139 -> 16690.74 | B5: ='CONSIGNAÇÕES FOLHA 1'!F187 -> 0 | C5: ='LÍQUIDO FOLHA -1'!H57 -> 3789.59
A6: ='CONSIGNAÇÕES FOLHA 1'!F131 -> 9974.28 | B6: ='CONSIGNAÇÕES FOLHA 1'!F196 -> 0 | C6: 0 | E6: 0 | F6: 0 | G6: 0 | H6: 0 | K6: 0 | O6: =SUM(O2:O4) -> 6257.76
A7: ='LÍQUIDO FOLHA -1'!G9 -> 0
A8: ='LÍQUIDO FOLHA -1'!G8 -> 0 | C8: =SUM(C2:C6) -> 84487.63 | D8: =SUM(D2:D7) -> 20769.55 | E8: =SUM(E2:E6) -> 70249.57 | F8: =SUM(F2:F6) -> 217794.06 | G8: =SUM(G2:G6) -> 50562.69 | H8: =SUM(H2:H6) -> 131.57 | K8: =SUM(K2:K6) -> 27883.07 | L8: =SUM(L2:L6) -> 43386.81 | M8: =SUM(M2:M7) -> 30402.26 | N8: =SUM(N2:N7) -> 3500
A9: =SUM(A2:A8) -> 90057.74
B10: =SUM(B2:B9) -> 52085.18 | G10: =G8-G4 -> 50514.25
K11: NAT- 31.91.13 | L11: =K8+O6 -> 34140.83
A12: =A9-A5 -> 73367 | E12: =E8+F8+G8+H8+I4 -> 338737.89 | K12: NAT.31.90.93 | L12: =L2+L3+M2+M3+M5+L4 -> 73789.07
A13: =A12-225 -> 73142 | B13: 13º 225
P16: =4*180000 -> 720000
E17: D E A | F17: D E A
A18: ='LÍQUIDO FOLHA -1'!F79 -> 694407.63 | B18: =A9+B10+C8+D8+E12+J4+K8+L8+M8+N8+O6+E24+F24 -> 704883.91 | C18: =C16-C17 -> 0 | E18: 31.90.92 | F18: 31.91.92 | K18: =E12-I21-G4-H4 -> 338671.47
B19: =A18-B18 -> -10476.28 | E19: ='LÍQUIDO FOLHA -1'!G41 -> 0 | F19: ='CONSIGNAÇÕES FOLHA 1'!F153 -> 1076.57 | L19: =L8+M8 -> 73789.07 | N19: =K8+O6 -> 34140.83
E20: ='LÍQUIDO FOLHA -1'!H26 -> 5448.82 | F20: ='CONSIGNAÇÕES FOLHA 1'!F161 -> 147.11 | H20: FUNDO | L20: =L19+N8+J4 -> 77289.07
E21: ='CONSIGNAÇÕES FOLHA 1'!F140 -> 0 | H21: PLANSAUDE
E22: ='LÍQUIDO FOLHA -1'!H55 -> 561.11 | F22: ='CONSIGNAÇÕES FOLHA 1'!F208 -> 82.41
E23: 0 | F23: 0
E24: =E19+E20+E21+E22 -> 6009.93 | F24: =SUM(F19:F23) -> 1306.09 | K24: =K2+K3 -> 23039.57 | L24: VENCIMENTOS | M24: SUBSIDIO
L25: =E8-624.12-85.86 -> 69539.59 | M25: =F3+F4 -> 189620.5
E44: =C41+E21 -> 0

Sheet Detalhe Consignacoes
A1: CONSIGNAÇÕES | B1: VALOR | C1: FUNGERP | D1: TOTAL GERAL | E1: BC
A2: SIND FISCAL | D2: ='CONSIGNAÇÕES FOLHA 1'!F50 -> 0 | E2: 0 | F2: =D2-E2 -> 0
A3: santander | D3: ='CONSIGNAÇÕES FOLHA 1'!F77 -> 0 | E3: 0.35 | F3: =D3-E3 -> -0.35
A4: sinfito | D4: ='CONSIGNAÇÕES FOLHA 1'!F55 -> 0 | E4: 0.34 | F4: =D4-E4 -> -0.34
A5: ASSECAD MENS | D5: ='CONSIGNAÇÕES FOLHA 1'!F31 -> 345.22 | E5: 3.74 | F5: =D5-E5 -> 341.48
A6: MEU CASH CARD | D6: ='CONSIGNAÇÕES FOLHA 1'!F75 -> 0 | E6: 1.45 | F6: =D6-E6 -> -1.45
A7: SICOOB PASSIVOS | D7: ='CONSIGNAÇÕES FOLHA 1'!F94 -> 0 | E7: 2.55 | F7: =D7-E7 -> -2.55 | G7: =F7+F8 -> -2.55 | H7: =E7+E8 -> 2.55
A8: SICOOB | D8: ='CONSIGNAÇÕES FOLHA 1'!F64 -> 0 | E8: 0 | F8: =D8-E8 -> 0 | G8: =C6+C7+C8 -> 0
A9: BB CRÉDITO FÁCIL | D9: ='CONSIGNAÇÕES FOLHA 1'!F41 -> 4979.09 | E9: 389.64 | F9: =D9-E9 -> 4589.45 | G9: =F9+F10 -> 9562.99 | H9: =E9+E10 -> 395.18
A10: bb passivos | D10: ='CONSIGNAÇÕES FOLHA 1'!F95 -> 4979.08 | E10: 5.54 | F10: =D10-E10 -> 4973.54
A11: BRADESCO EMPRÉSTIMO | D11: ='CONSIGNAÇÕES FOLHA 1'!F45 -> 0 | E11: 27.74 | F11: =D11-E11 -> -27.74
A12: PANAMERICANO | D12: ='CONSIGNAÇÕES FOLHA 1'!F96 -> 0 | E12: 12.16 | F12: =D12-E12 -> -12.16
A13: FUTURO PREVI | D13: ='CONSIGNAÇÕES FOLHA 1'!F74 -> 0 | E13: 3.95 | F13: =D13-E13 -> -3.95
A14: SISEPE | D14: ='CONSIGNAÇÕES FOLHA 1'!F52 -> 345.22 | E14: 6.17 | F14: =D14-E14 -> 339.05
A15: AGEPOL-TO | D15: ='CONSIGNAÇÕES FOLHA 1'!F59 -> 0 | E15: 0 | F15: =D15-E15 -> 0
A16: SINDEPOL | D16: ='CONSIGNAÇÕES FOLHA 1'!F44 -> 0 | E16: 1.9 | F16: =D16-E16 -> -1.9
A17: SINPOL | D17: ='CONSIGNAÇÕES FOLHA 1'!F58 -> 253.61 | E17: 1.21 | F17: =D17-E17 -> 252.4
A18: SINTRAS | D18: ='CONSIGNAÇÕES FOLHA 1'!F51 -> 0 | E18: 1.1 | F18: =D18-E18 -> -1.1
A19: SEET | D19: ='CONSIGNAÇÕES FOLHA 1'!F57 -> 0 | E19: 1.33 | F19: =D19-E19 -> -1.33
A20: QISTA S/A | D20: ='CONSIGNAÇÕES FOLHA 1'!F82 -> 0 | E20: 4.15 | F20: =D20-E20 -> -4.15
A21: CLICKBANK | D21: ='CONSIGNAÇÕES FOLHA 1'!F79 -> 0 | E21: 0 | F21: =D21-E21 -> 0
A22: CAIXA | D22: ='CONSIGNAÇÕES FOLHA 1'!F56 -> 2104.28 | E22: 124.23 | F22: =D22-E22 -> 1980.05
A23: AJUP | D23: ='CONSIGNAÇÕES FOLHA 1'!F85 -> 66.78 | E23: 0.87 | F23: =D23-E23 -> 65.91
A24: CAPIT CONSIG | D24: ='CONSIGNAÇÕES FOLHA 1'!F53 -> 0 | E24: 11.36 | F24: =D24-E24 -> -11.36
A25: PECULIO UNIÃO | D25: ='CONSIGNAÇÕES FOLHA 1'!F84 -> 0 | E25: 33.32 | F25: =D25-E25 -> -33.32
A26: vem card | D26: ='CONSIGNAÇÕES FOLHA 1'!F80 -> 0 | E26: 1.11 | F26: =D26-E26 -> -1.11
A27: BRB - BANCO BRASILIA | D27: ='CONSIGNAÇÕES FOLHA 1'!F87 -> 3024.5 | E27: 0 | F27: =D27-E27 -> 3024.5
A28: BANCO DAYCOVAL | D28: ='CONSIGNAÇÕES FOLHA 1'!F63 -> 1284.71 | E28: 24.31 | F28: =D28-E28 -> 1260.4
A29: BCO INDUSTRIAL | D29: ='CONSIGNAÇÕES FOLHA 1'!F54 -> 0 | E29: 14.32 | F29: =D29-E29 -> -14.32
A30: CIASPREV | D30: ='CONSIGNAÇÕES FOLHA 1'!F65 -> 0 | E30: 22.08 | F30: =D30-E30 -> -22.08 | G30: =F30+F31+F32 -> -29.43 | H30: =E30+E31+E32 -> 69.43
A31: CIASPREV | D31: ='CONSIGNAÇÕES FOLHA 1'!F66 -> 0 | E31: 44.6 | F31: =D31-E31 -> -44.6
A32: CIASPREV | D32: ='CONSIGNAÇÕES FOLHA 1'!F67 -> 40 | E32: 2.75 | F32: =D32-E32 -> 37.25 | G32: =C30+C31+C32 -> 0
A33: AVANCARD | D33: ='CONSIGNAÇÕES FOLHA 1'!F83 -> 0 | E33: 0 | F33: =D33-E33 -> 0
A34: webcash - 3336 | D34: ='CONSIGNAÇÕES FOLHA 1'!F91 -> 0 | E34: 1.21 | F34: =D34-E34 -> -1.21 | G34: =F34+F35+F36 -> -1.21
A35: webcash - 3634 | D35: ='CONSIGNAÇÕES FOLHA 1'!F92 -> 0 | E35: 0 | F35: =D35-E35 -> 0
A36: webcash - 3634 | D36: ='CONSIGNAÇÕES FOLHA 1'!F93 -> 0 | E36: 0 | F36: =D36-E36 -> 0
A37: BRB -PASSIVOS | D37: ='CONSIGNAÇÕES FOLHA 1'!F86 -> 3144.15 | E37: 194.53 | F37: =D37-E37 -> 2949.62 | G37: =F37+F27 -> 5974.12 | H37: =E27+E37 -> 194.53
C38: =SUM(C2:C37) -> 0 | E38: =SUM(E2:E37) -> 938.01
A42: RGPS | B42: VALOR | C42: FUNGERP | D42: TOTAL GERAL
A43: ASSECAD | B43: ='CONSIGNAÇÕES FOLHA 1'!G31 -> 49.86 | C43: 1.49 | D43: =B43-C43 -> 48.37
...

Sheet Listas
A1: Naturezas (Liquido Folha) | B1: Bancos/Instituicoes (Consignacoes)
A2: 3.31.90.04.01 | B2: FUNDO DE PREVIDÊNCIA (FUNDO FINANCEIRO)
A3: 3.31.90.04.02 | B3: FUNDO DE PREVIDÊNCIA - FDO FINANCEIRO (31.90.92) DEA
A4: 3.31.90.13.02 | B4: FUNDO PREVIDÊNCIARIO segurado
A5: 3.31.90.04.45 | B5: FUNDO PREVIDÊNCIARIO (31.90.92) DEA
A6: 3.31.90.92.04 | B6: INSS
A7: 3.33.90.46 | B7: INSS (92) DEA
A8: 33.90.92 | B8: IRRF
A9: 3.31.90.94.01 | B9: PREV REQU (MUNICIPIO GURUPI - MANTIS)
A10: 3.31.90.05.07 | B10: INSTITUTO DE SEG. MUNICIPAL DE GOIÁS
A11: 3.31.90.11.43 | B11: INSTITUTO DE SEG. MUNICIPAL DE GOIÁS (31.90.92) DEA
A12: 31.90.11.07 | B12: PREVIPALMAS REQUISITADO
... A23: 3.31.90.92.12 | B23: ASSER-RURALTINS (PLANO DE SAÚDE
B24: ASSINE COMPARTICIPAÇÃO
B25: ASSINE MENSALIDADE
B26: ASSINE PLANO DE SAÚDE
B27: Bonsucesso – cartão de credito
B28: BANCO BONSUCESSO S/A
B29: BB CRÉD. FÁCIL (BB CONSIGNAÇÃO)
B30: BMG – CARTÃO DE CREDITO
B31: BMG CONSIGNAÇÃO
B32: SINDEPOL - SIND. DOS DEL. (mensalidade)
B33: BRADESCO - CONSIGNAÇÕES
B34: SINFITO
B35: PRODIVINO EMPRESTIMO
... B84: FUNGERP
